Workbook

Sheet Vstupy
A1: Cleansia – cenový model v3 (ceny se počítají, nezadávají)
A2: Modré buňky jsou vstupy. Ceny balíčků, doplňků i příplatků se dopočítají tak, aby uklízečka měla cílovou sazbu a platformě zbyl cílový příspěvek po DPH a všech ztrátách.
A4: 1. Odměna uklízečky – vstup, ze kterého se počítá cena
A5: Cílová odměna uklízečky | B5: 300 | D5: Kč/h | E5: Zadání JJ. Tohle je kotva celého ceníku.
A6: Je cíl čistý po jejích nákladech? (ANO/NE) | B6: NE | E6: NE = 300 Kč/h fakturuje a chemii s dopravou si z toho platí. ANO = 300 Kč/h jí zbude čistých a sazba se o náklady zvedne.
A7: Vlastní náklady uklízečky (chemie + doprava) | B7: 65 | D7: Kč/h | E7: Ceník v3: chemie 25 + doprava 40.
A8: Fakturovaná sazba uklízečky | B8: =IF(B6="ANO",B5+B7,B5) -> 300 | D8: Kč/h | E8: Tuto částku jí platíme za hodinu práce.
A9: Čistý výdělek uklízečky | B9: =B8-B7 -> 235 | D9: Kč/h | E9: Co jí reálně zbude po vlastních nákladech.
A11: 2. Cílová rentabilita platformy
A12: Cílový příspěvek na úhradu | B12: 0.18 | D12: % z ceny | E12: Kolik z ceny má zbýt po DPH, poplatcích, slevách, stornech a marketingu. 18 % je konzervativní; 22–25 % je zdravější.
A13: Minimální cena zakázky | B13: 690 | D13: Kč | E13: Pod tuto částku se zakázka neprodává – malé zakázky nepokryjí fixní náklady.
A14: Zaokrouhlení cen nahoru na | B14: 10 | D14: Kč | E14: Ceny se zaokrouhlují nahoru, nikdy dolů – dolů by shodilo cílovou marži.
A16: 3. Pracnost úklidu | B16: Ceník v3 | C16: Reálný odhad
A17: Standardní úklid | B17: 1.2 | C17: 3 | D17: min/m² | E17: 1,2 min/m² = 2+kk za hodinu. V praxi neudržitelné.
A18: Deep clean | B18: 2.5 | C18: 5 | D18: min/m² | E18: 5 min/m² = 90 m² za 7,5 h.
A19: Po rekonstrukci | B19: 3.8 | C19: 7 | D19: min/m² | E19: Nejvyšší rozptyl, ověřit na prvních zakázkách.
A20: Použít variantu (CENÍK / REÁL) | B20: REÁL | E20: Nejcitlivější přepínač v sešitě. Po prvních 20 zakázkách nahraď sloupec C měřenou skutečností.
A21: Aktivní pracnost – standard | B21: =IF($B$20="CENÍK",B17,C17) -> 3 | D21: min/m²
A22: Aktivní pracnost – deep | B22: =IF($B$20="CENÍK",B18,C18) -> 5 | D22: min/m²
A23: Aktivní pracnost – po rekonstrukci | B23: =IF($B$20="CENÍK",B19,C19) -> 7 | D23: min/m²
A25: 4. Ztráty a poplatky
A26: Stripe – procentní poplatek | B26: 0.014 | D26: % | E26: Evropské karty. Mimoevropské 2,9 %+.
A27: Stripe – fixní poplatek | B27: 6 | D27: Kč | E27: Na transakci.
A28: Vážená sleva (Plus, tier, promo) | B28: 0.04 | D28: % | E28: Strop Plus + tier je 12 %, promokódy 10–20 %.
A29: Storna a refundace | B29: 0.02 | D29: %
A30: Reklamace a částečné refundace | B30: 0.02 | D30: % | E30: Odměna uklízečky se přitom nevrací.
A31: Chargebacky | B31: 0.003 | D31: %
A32: Pravděpodobnost neobsazené zakázky | B32: 0.015 | D32: % | E32: Plná refundace + garanční kredit.
A33: Garanční kredit za nedostavení | B33: 250 | D33: Kč | E33: Mike navrhuje až 500 Kč – zkus si přepsat a sleduj ceny.
A34: Marketing / CAC na zakázku | B34: 120 | D34: Kč | E34: Odhad. Tohle číslo tlačí ceny malých zakázek nahoru nejvíc.
A35: Procentní ztráty celkem (bez DPH) | B35: =B26+B28+B29+B30+B31 -> 0.097 | D35: %
A36: Fixní náklady na zakázku | B36: =B27+B32*B33+B34 -> 129.75 | D36: Kč | E36: Stripe fix + očekávaný kredit + marketing.
A38: 5. DPH
A39: Je Cleansia plátce DPH? (ANO/NE) | B39: ANO | E39: Uklízečky jsou neplátci – z jejich faktury není nárok na odpočet.
A40: Sazba DPH | B40: 0.21 | D40: %
A41: Efektivní odvod z ceny vč. DPH | B41: =IF(B39="ANO",B40/(1+B40),0) -> 0.17355372 | D41: % | E41: 17,4 % z každé ceny. Největší jednotlivá položka po odměně.
A43: 6. Cenový vzorec
A44: Celkové procentní zatížení ceny | B44: =B41+B35 -> 0.27055372 | D44: % | E44: DPH + poplatky + slevy + ztráty.
A45: Dělitel cenového vzorce | B45: =1-B44-B12 -> 0.54944628 | E45: 1 − zatížení − cílový příspěvek.
A46: Kontrola dělitele | B46: =IF(B45<=0.1,"POZOR: cílová marže je při tomto zatížení nedosažitelná","OK") -> OK | E46: Když se sem dostane POZOR, sniž cílový příspěvek nebo zatížení.
...

Sheet Metodika
A1: Jak se cena počítá – krok za krokem na jednom příkladu
A2: Příklad: DEEP clean bytu 3+kk (72,5 m²). Všechny hodnoty se berou z listu Vstupy.
A4: Plocha (m²) | B4: =Balíčky!E10 -> 72.5 | C4: Střed intervalu 60–85 m².
A5: Pracnost (min/m²) | B5: =Vstupy!B22 -> 5 | C5: Deep clean.
A6: Hodin práce | B6: =B4*B5/60 -> 6.0416667 | C6: Plocha × pracnost ÷ 60.
A7: Odměna uklízečky | B7: =B6*Vstupy!B8 -> 1812.5 | C7: Hodiny × fakturovaná sazba.
A8: Fixní náklady na zakázku | B8: =Vstupy!B36 -> 129.75 | C8: Stripe fix + očekávaný kredit + marketing.
A9: Součet, který musí cena pokrýt | B9: =B7+B8 -> 1942.25 | C9: Odměna + fixní náklady.
A10: Dělitel | B10: =Vstupy!B45 -> 0.54944628 | C10: 1 − zatížení − cílový příspěvek.
A11: Minimální cena | B11: =B9/B10 -> 3534.9225 | C11: Součet ÷ dělitel.
A12: Cena po zaokrouhlení | B12: =CEILING(B11,Vstupy!B14) -> 3540 | C12: Zaokrouhleno nahoru na násobek z Vstupy!B14.
A13: Z toho odvod DPH | B13: =B12*Vstupy!B41 -> 614.38017
A14: Z toho poplatky, slevy a ztráty | B14: =B12*Vstupy!B35 -> 343.38
A15: Z toho odměna uklízečky | B15: =B7 -> 1812.5
A16: Z toho fixní náklady | B16: =B8 -> 129.75
A17: Zbývá jako příspěvek | B17: =B12-B13-B14-B15-B16 -> 639.98983 | C17: Musí být ≥ cílový příspěvek.
A18: Příspěvek v % | B18: =B17/B12 -> 0.18078809
A21: Proč je to postavené takhle
A22: Minulá verze brala ceny z Ceníku v3 jako dané a počítala, co zbude – a vycházelo, že uklízečka má 200–250 Kč/h a marže je 4–20 %. Tahle verze obrací směr výpočtu: zadáš, co má mít uklízečka a co máš mít ty, a vyjde cena.

Sheet Balíčky
A1: Nový ceník balíčků – dopočítaný z cílové odměny a cílové marže
A2: Sloupec L je cena do ceníku. Sloupce P a Q dokazují, že marže sedí u každého řádku.
A4: Balíček | B4: Dispozice | C4: m² od | D4: m² do | E4: m² střed | F4: Typ | G4: Pracnost min/m² | H4: Hodin | I4: Odměna uklízečky | J4: Fixní náklady | K4: Minimální cena | L4: CENA NOVÁ | M4: Kč/h pro zákazníka | N4: Podíl uklízečky z ceny | O4: Příspěvek Kč | P4: Příspěvek % | Q4: Kontrola | R4: Cena v Ceníku v3 | S4: Změna
A5: S | B5: 1+kk | C5: 25 | D5: 35 | E5: =AVERAGE(C5:D5) -> 30 | F5: ESSENTIAL | G5: =IF(F5="DEEP",Vstupy!$B$22,Vstupy!$B$21) -> 3 | H5: =E5*G5/60 -> 1.5 | I5: =H5*Vstupy!$B$8 -> 450 | J5: =Vstupy!$B$36 -> 129.75 | K5: =(I5+J5)/Vstupy!$B$45 -> 1055.1532 | L5: =MAX(CEILING(K5,Vstupy!$B$14),Vstupy!$B$13) -> 1060 | M5: =L5/H5 -> 706.66667 | N5: =I5/L5 -> 0.4245283 | O5: =L5-L5*(Vstupy!$B$41+Vstupy!$B$35)-I5-J5 -> 193.46306 | P5: =O5/L5 -> 0.18251232 | Q5: =IF(P5>=Vstupy!$B$12-0.001,"OK","POD CÍLEM") -> OK | R5: 690 | S5: =L5/R5-1 -> 0.53623188
A6: S | B6: 1+kk | C6: 25 | D6: 35 | E6: =AVERAGE(C6:D6) -> 30 | F6: DEEP | G6: =IF(F6="DEEP",Vstupy!$B$22,Vstupy!$B$21) -> 5 | H6: =E6*G6/60 -> 2.5 | I6: =H6*Vstupy!$B$8 -> 750 | J6: =Vstupy!$B$36 -> 129.75 | K6: =(I6+J6)/Vstupy!$B$45 -> 1601.1574 | L6: =MAX(CEILING(K6,Vstupy!$B$14),Vstupy!$B$13) -> 1610 | M6: =L6/H6 -> 644 | N6: =I6/L6 -> 0.46583851 | O6: =L6-L6*(Vstupy!$B$41+Vstupy!$B$35)-I6-J6 -> 294.65851 | P6: =O6/L6 -> 0.18301771 | Q6: =IF(P6>=Vstupy!$B$12-0.001,"OK","POD CÍLEM") -> OK | R6: 1490 | S6: =L6/R6-1 -> 0.080536913
A7: M | B7: 2+kk / 2+1 | C7: 40 | D7: 60 | E7: =AVERAGE(C7:D7) -> 50 | F7: ESSENTIAL | G7: =IF(F7="DEEP",Vstupy!$B$22,Vstupy!$B$21) -> 3 | H7: =E7*G7/60 -> 2.5 | I7: =H7*Vstupy!$B$8 -> 750 | J7: =Vstupy!$B$36 -> 129.75 | K7: =(I7+J7)/Vstupy!$B$45 -> 1601.1574 | L7: =MAX(CEILING(K7,Vstupy!$B$14),Vstupy!$B$13) -> 1610 | M7: =L7/H7 -> 644 | N7: =I7/L7 -> 0.46583851 | O7: =L7-L7*(Vstupy!$B$41+Vstupy!$B$35)-I7-J7 -> 294.65851 | P7: =O7/L7 -> 0.18301771 | Q7: =IF(P7>=Vstupy!$B$12-0.001,"OK","POD CÍLEM") -> OK | R7: 1090 | S7: =L7/R7-1 -> 0.47706422
A8: M | B8: 2+kk / 2+1 | C8: 40 | D8: 60 | E8: =AVERAGE(C8:D8) -> 50 | F8: DEEP | G8: =IF(F8="DEEP",Vstupy!$B$22,Vstupy!$B$21) -> 5 | H8: =E8*G8/60 -> 4.1666667 | I8: =H8*Vstupy!$B$8 -> 1250 | J8: =Vstupy!$B$36 -> 129.75 | K8: =(I8+J8)/Vstupy!$B$45 -> 2511.1645 | L8: =MAX(CEILING(K8,Vstupy!$B$14),Vstupy!$B$13) -> 2520 | M8: =L8/H8 -> 604.8 | N8: =I8/L8 -> 0.49603175 | O8: =L8-L8*(Vstupy!$B$41+Vstupy!$B$35)-I8-J8 -> 458.45463 | P8: =O8/L8 -> 0.18192644 | Q8: =IF(P8>=Vstupy!$B$12-0.001,"OK","POD CÍLEM") -> OK | R8: 2090 | S8: =L8/R8-1 -> 0.20574163
A9: L | B9: 3+kk / 3+1 | C9: 60 | D9: 85 | E9: =AVERAGE(C9:D9) -> 72.5 | F9: ESSENTIAL | G9: =IF(F9="DEEP",Vstupy!$B$22,Vstupy!$B$21) -> 3 | H9: =E9*G9/60 -> 3.625 | I9: =H9*Vstupy!$B$8 -> 1087.5 | J9: =Vstupy!$B$36 -> 129.75 | K9: =(I9+J9)/Vstupy!$B$45 -> 2215.4122 | L9: =MAX(CEILING(K9,Vstupy!$B$14),Vstupy!$B$13) -> 2220 | M9: =L9/H9 -> 612.41379 | N9: =I9/L9 -> 0.48986486 | O9: =L9-L9*(Vstupy!$B$41+Vstupy!$B$35)-I9-J9 -> 402.12074 | P9: =O9/L9 -> 0.18113547 | Q9: =IF(P9>=Vstupy!$B$12-0.001,"OK","POD CÍLEM") -> OK | R9: 1590 | S9: =L9/R9-1 -> 0.39622642
A10: L | B10: 3+kk / 3+1 | C10: 60 | D10: 85 | E10: =AVERAGE(C10:D10) -> 72.5 | F10: DEEP | G10: =IF(F10="DEEP",Vstupy!$B$22,Vstupy!$B$21) -> 5 | H10: =E10*G10/60 -> 6.0416667 | I10: =H10*Vstupy!$B$8 -> 1812.5 | J10: =Vstupy!$B$36 -> 129.75 | K10: =(I10+J10)/Vstupy!$B$45 -> 3534.9225 | L10: =MAX(CEILING(K10,Vstupy!$B$14),Vstupy!$B$13) -> 3540 | M10: =L10/H10 -> 585.93103 | N10: =I10/L10 -> 0.51200565 | O10: =L10-L10*(Vstupy!$B$41+Vstupy!$B$35)-I10-J10 -> 639.98983 | P10: =O10/L10 -> 0.18078809 | Q10: =IF(P10>=Vstupy!$B$12-0.001,"OK","POD CÍLEM") -> OK | R10: 2890 | S10: =L10/R10-1 -> 0.22491349
A11: XL | B11: 4+kk / 4+1 | C11: 85 | D11: 120 | E11: =AVERAGE(C11:D11) -> 102.5 | F11: ESSENTIAL | G11: =IF(F11="DEEP",Vstupy!$B$22,Vstupy!$B$21) -> 3 | H11: =E11*G11/60 -> 5.125 | I11: =H11*Vstupy!$B$8 -> 1537.5 | J11: =Vstupy!$B$36 -> 129.75 | K11: =(I11+J11)/Vstupy!$B$45 -> 3034.4186 | L11: =MAX(CEILING(K11,Vstupy!$B$14),Vstupy!$B$13) -> 3040 | M11: =L11/H11 -> 593.17073 | N11: =I11/L11 -> 0.50575658 | O11: =L11-L11*(Vstupy!$B$41+Vstupy!$B$35)-I11-J11 -> 550.26669 | P11: =O11/L11 -> 0.18100878 | Q11: =IF(P11>=Vstupy!$B$12-0.001,"OK","POD CÍLEM") -> OK | R11: 2190 | S11: =L11/R11-1 -> 0.38812785
A12: XL | B12: 4+kk / 4+1 | C12: 85 | D12: 120 | E12: =AVERAGE(C12:D12) -> 102.5 | F12: DEEP | G12: =IF(F12="DEEP",Vstupy!$B$22,Vstupy!$B$21) -> 5 | H12: =E12*G12/60 -> 8.5416667 | I12: =H12*Vstupy!$B$8 -> 2562.5 | J12: =Vstupy!$B$36 -> 129.75 | K12: =(I12+J12)/Vstupy!$B$45 -> 4899.9331 | L12: =MAX(CEILING(K12,Vstupy!$B$14),Vstupy!$B$13) -> 4900 | M12: =L12/H12 -> 573.65854 | N12: =I12/L12 -> 0.52295918 | O12: =L12-L12*(Vstupy!$B$41+Vstupy!$B$35)-I12-J12 -> 882.03678 | P12: =O12/L12 -> 0.18000751 | Q12: =IF(P12>=Vstupy!$B$12-0.001,"OK","POD CÍLEM") -> OK | R12: 3890 | S12: =L12/R12-1 -> 0.2596401
A13: XXL | B13: dům 5+ | C13: 120 | D13: 180 | E13: =AVERAGE(C13:D13) -> 150 | F13: ESSENTIAL | G13: =IF(F13="DEEP",Vstupy!$B$22,Vstupy!$B$21) -> 3 | H13: =E13*G13/60 -> 7.5 | I13: =H13*Vstupy!$B$8 -> 2250 | J13: =Vstupy!$B$36 -> 129.75 | K13: =(I13+J13)/Vstupy!$B$45 -> 4331.1786 | L13: =MAX(CEILING(K13,Vstupy!$B$14),Vstupy!$B$13) -> 4340 | M13: =L13/H13 -> 578.66667 | N13: =I13/L13 -> 0.51843318 | O13: =L13-L13*(Vstupy!$B$41+Vstupy!$B$35)-I13-J13 -> 786.04686 | P13: =O13/L13 -> 0.18111679 | Q13: =IF(P13>=Vstupy!$B$12-0.001,"OK","POD CÍLEM") -> OK | R13: 2990 | S13: =L13/R13-1 -> 0.45150502
A14: XXL | B14: dům 5+ | C14: 120 | D14: 180 | E14: =AVERAGE(C14:D14) -> 150 | F14: DEEP | G14: =IF(F14="DEEP",Vstupy!$B$22,Vstupy!$B$21) -> 5 | H14: =E14*G14/60 -> 12.5 | I14: =H14*Vstupy!$B$8 -> 3750 | J14: =Vstupy!$B$36 -> 129.75 | K14: =(I14+J14)/Vstupy!$B$45 -> 7061.1999 | L14: =MAX(CEILING(K14,Vstupy!$B$14),Vstupy!$B$13) -> 7070 | M14: =L14/H14 -> 565.6 | N14: =I14/L14 -> 0.53041018 | O14: =L14-L14*(Vstupy!$B$41+Vstupy!$B$35)-I14-J14 -> 1277.4352 | P14: =O14/L14 -> 0.1806839 | Q14: =IF(P14>=Vstupy!$B$12-0.001,"OK","POD CÍLEM") -> OK | R14: 5290 | S14: =L14/R14-1 -> 0.33648393
A15: PRŮMĚR | H15: =AVERAGE(H5:H14) -> 5.4 | I15: =AVERAGE(I5:I14) -> 1620 | L15: =AVERAGE(L5:L14) -> 3191 | M15: =AVERAGE(M5:M14) -> 610.89074 | N15: =AVERAGE(N5:N14) -> 0.49316667 | O15: =AVERAGE(O5:O14) -> 577.91308 | P15: =AVERAGE(P5:P14) -> 0.18152147 | R15: =AVERAGE(R5:R14) -> 2420 | S15: =AVERAGE(S5:S14) -> 0.33564715
A17: Sloupec M je cena za hodinu práce, kterou zákazník fakticky platí. Konkurence (CleanWhale) se pohybuje 300–500 Kč/h, ale u ní uklízečka nemá 300 Kč/h čistých a část služeb je bez DPH. Pokud vyjde M výrazně nad 600 Kč/h, máš tři páky: snížit cílový příspěvek, snížit CAC, nebo přiznat, že reálná pracnost je nižší.
A18: Sloupec N ukazuje, kolik z ceny jde uklízečce. To je opak provize: provize platformy je 1 − N. Vychází vyšší než dnešních 50 %, protože z ní musíš zaplatit i DPH.

Sheet Doplňky
A1: Doplňkové služby – přeceněno stejným vzorcem
A2: U doplňků se nepočítá marketing ani Stripe fix znovu (jedou na stejné objednávce), počítá se čas, materiál a procentní zatížení.
A4: Doplněk | B4: Čas (h) | C4: Materiál | D4: Odměna uklízečky | E4: Nákladová cena | F4: Cena dle vzorce | G4: Příspěvek Kč | H4: Příspěvek % | I4: Cena v Ceníku v3 | J4: Změna | K4: DOPORUČENÁ CENA | L4: Příspěvek % při doporučené | M4: Poznámka
A5: Mytí lednice zevnitř | B5: 0.5 | C5: 30 | D5: =B5*Vstupy!$B$8 -> 150 | E5: =(D5+C5)/Vstupy!$B$45 -> 327.60255 | F5: =CEILING(E5,Vstupy!$B$14) -> 330 | G5: =F5-F5*(Vstupy!$B$41+Vstupy!$B$35)-D5-C5 -> 60.717273 | H5: =G5/F5 -> 0.18399174 | I5: 320 | J5: =F5/I5-1 -> 0.03125 | K5: =MAX(F5,I5) -> 330 | L5: =(K5-K5*(Vstupy!$B$41+Vstupy!$B$35)-D5-C5)/K5 -> 0.18399174
A6: Mytí trouby (rozložení) | B6: 0.75 | C6: 60 | D6: =B6*Vstupy!$B$8 -> 225 | E6: =(D6+C6)/Vstupy!$B$45 -> 518.70403 | F6: =CEILING(E6,Vstupy!$B$14) -> 520 | G6: =F6-F6*(Vstupy!$B$41+Vstupy!$B$35)-D6-C6 -> 94.312066 | H6: =G6/F6 -> 0.18136936 | I6: 420 | J6: =F6/I6-1 -> 0.23809524 | K6: =MAX(F6,I6) -> 520 | L6: =(K6-K6*(Vstupy!$B$41+Vstupy!$B$35)-D6-C6)/K6 -> 0.18136936
A7: Žehlení (1 hodina) | B7: 1 | C7: 5 | D7: =B7*Vstupy!$B$8 -> 300 | E7: =(D7+C7)/Vstupy!$B$45 -> 555.10431 | F7: =CEILING(E7,Vstupy!$B$14) -> 560 | G7: =F7-F7*(Vstupy!$B$41+Vstupy!$B$35)-D7-C7 -> 103.48992 | H7: =G7/F7 -> 0.18480342 | I7: 220 | J7: =F7/I7-1 -> 1.5454545 | K7: =MAX(F7,I7) -> 560 | L7: =(K7-K7*(Vstupy!$B$41+Vstupy!$B$35)-D7-C7)/K7 -> 0.18480342 | M7: Původní cena byla pod sazbou uklízečky – nová ji pokrývá.
A8: Čištění koberce parou (10 m²) | B8: 1.5 | C8: 120 | D8: =B8*Vstupy!$B$8 -> 450 | E8: =(D8+C8)/Vstupy!$B$45 -> 1037.4081 | F8: =CEILING(E8,Vstupy!$B$14) -> 1040 | G8: =F8-F8*(Vstupy!$B$41+Vstupy!$B$35)-D8-C8 -> 188.62413 | H8: =G8/F8 -> 0.18136936 | I8: 1400 | J8: =F8/I8-1 -> -0.25714286 | K8: =MAX(F8,I8) -> 1400 | L8: =(K8-K8*(Vstupy!$B$41+Vstupy!$B$35)-D8-C8)/K8 -> 0.32230342 | M8: Materiál zahrnuje spotřebu; amortizace stroje zvlášť.
A9: Parní dezinfekce matrace | B9: 0.75 | C9: 60 | D9: =B9*Vstupy!$B$8 -> 225 | E9: =(D9+C9)/Vstupy!$B$45 -> 518.70403 | F9: =CEILING(E9,Vstupy!$B$14) -> 520 | G9: =F9-F9*(Vstupy!$B$41+Vstupy!$B$35)-D9-C9 -> 94.312066 | H9: =G9/F9 -> 0.18136936 | I9: 790 | J9: =F9/I9-1 -> -0.34177215 | K9: =MAX(F9,I9) -> 790 | L9: =(K9-K9*(Vstupy!$B$41+Vstupy!$B$35)-D9-C9)/K9 -> 0.36868679
A10: Impregnace čalounění (sedačka) | B10: 0.75 | C10: 120 | D10: =B10*Vstupy!$B$8 -> 225 | E10: =(D10+C10)/Vstupy!$B$45 -> 627.90488 | F10: =CEILING(E10,Vstupy!$B$14) -> 630 | G10: =F10-F10*(Vstupy!$B$41+Vstupy!$B$35)-D10-C10 -> 114.55116 | H10: =G10/F10 -> 0.18182723 | I10: 590 | J10: =F10/I10-1 -> 0.06779661 | K10: =MAX(F10,I10) -> 630 | L10: =(K10-K10*(Vstupy!$B$41+Vstupy!$B$35)-D10-C10)/K10 -> 0.18182723
A11: Ozónová dezinfekce | B11: 1 | C11: 100 | D11: =B11*Vstupy!$B$8 -> 300 | E11: =(D11+C11)/Vstupy!$B$45 -> 728.00566 | F11: =CEILING(E11,Vstupy!$B$14) -> 730 | G11: =F11-F11*(Vstupy!$B$41+Vstupy!$B$35)-D11-C11 -> 132.49579 | H11: =G11/F11 -> 0.18150108 | I11: 1690 | J11: =F11/I11-1 -> -0.56804734 | K11: =MAX(F11,I11) -> 1690 | L11: =(K11-K11*(Vstupy!$B$41+Vstupy!$B$35)-D11-C11)/K11 -> 0.49275989 | M11: Stroj pracuje bez lidí – čas uklízečky je jen obsluha.
A12: Úklid sklepa / garáže (1 hodina) | B12: 1 | C12: 20 | D12: =B12*Vstupy!$B$8 -> 300 | E12: =(D12+C12)/Vstupy!$B$45 -> 582.40452 | F12: =CEILING(E12,Vstupy!$B$14) -> 590 | G12: =F12-F12*(Vstupy!$B$41+Vstupy!$B$35)-D12-C12 -> 110.37331 | H12: =G12/F12 -> 0.1870734 | I12: 450 | J12: =F12/I12-1 -> 0.31111111 | K12: =MAX(F12,I12) -> 590 | L12: =(K12-K12*(Vstupy!$B$41+Vstupy!$B$35)-D12-C12)/K12 -> 0.1870734
A13: Mytí oken + rámy (10 m² skla) | B13: 1.5 | C13: 40 | D13: =B13*Vstupy!$B$8 -> 450 | E13: =(D13+C13)/Vstupy!$B$45 -> 891.80693 | F13: =CEILING(E13,Vstupy!$B$14) -> 900 | G13: =F13-F13*(Vstupy!$B$41+Vstupy!$B$35)-D13-C13 -> 166.50165 | H13: =G13/F13 -> 0.18500184 | I13: 990 | J13: =F13/I13-1 -> -0.090909091 | K13: =MAX(F13,I13) -> 990 | L13: =(K13-K13*(Vstupy!$B$41+Vstupy!$B$35)-D13-C13)/K13 -> 0.23449679
A15: Vzorec dává cenovou PODLAHU, ne strop. Tam, kde původní ceník účtoval víc (ozón, matrace, tepování), cenu nesnižuj – trh ji akceptuje a marže je pak vyšší. Proto je závazný sloupec K.
A16: Doplňky jsou jediné místo, kde se dá marže zvednout bez zdražování základní služby. Prodávej je jako zaškrtávátka v košíku, ne jako samostatnou objednávku – jinak jim narostou fixní náklady.

Sheet Příplatky
A1: Modifikátory a příplatky
A2: Počítáno z času navíc a materiálu, stejným vzorcem. Procentní příplatky (expres, premium) se násobí z výsledné ceny.
A4: Položka | B4: Čas navíc (min) | C4: Materiál | D4: Odměna uklízečky | E4: CENA NOVÁ | F4: Příspěvek % | G4: Cena v Ceníku v3 | H4: Poznámka
A5: Pokoj navíc – ESSENTIAL | B5: 35 | C5: 5 | D5: =B5/60*Vstupy!$B$8 -> 175 | E5: =CEILING((D5+C5)/Vstupy!$B$45,Vstupy!$B$14) -> 330 | F5: =(E5-E5*(Vstupy!$B$41+Vstupy!$B$35)-D5-C5)/E5 -> 0.18399174 | G5: 220
A6: Pokoj navíc – DEEP | B6: 60 | C6: 10 | D6: =B6/60*Vstupy!$B$8 -> 300 | E6: =CEILING((D6+C6)/Vstupy!$B$45,Vstupy!$B$14) -> 570 | F6: =(E6-E6*(Vstupy!$B$41+Vstupy!$B$35)-D6-C6)/E6 -> 0.18558663 | G6: 380
A7: Koupelna navíc – ESSENTIAL | B7: 45 | C7: 10 | D7: =B7/60*Vstupy!$B$8 -> 225 | E7: =CEILING((D7+C7)/Vstupy!$B$45,Vstupy!$B$14) -> 430 | F7: =(E7-E7*(Vstupy!$B$41+Vstupy!$B$35)-D7-C7)/E7 -> 0.18293465 | G7: 290
A8: Koupelna navíc – DEEP | B8: 80 | C8: 20 | D8: =B8/60*Vstupy!$B$8 -> 400 | E8: =CEILING((D8+C8)/Vstupy!$B$45,Vstupy!$B$14) -> 770 | F8: =(E8-E8*(Vstupy!$B$41+Vstupy!$B$35)-D8-C8)/E8 -> 0.18399174 | G8: 520
A9: Kuchyně navíc / velká otevřená – ESSENTIAL | B9: 55 | C9: 15 | D9: =B9/60*Vstupy!$B$8 -> 275 | E9: =CEILING((D9+C9)/Vstupy!$B$45,Vstupy!$B$14) -> 530 | F9: =(E9-E9*(Vstupy!$B$41+Vstupy!$B$35)-D9-C9)/E9 -> 0.18227647 | G9: 390
A10: Kuchyně navíc – DEEP | B10: 100 | C10: 25 | D10: =B10/60*Vstupy!$B$8 -> 500 | E10: =CEILING((D10+C10)/Vstupy!$B$45,Vstupy!$B$14) -> 960 | F10: =(E10-E10*(Vstupy!$B$41+Vstupy!$B$35)-D10-C10)/E10 -> 0.18257128 | G10: 720
A11: Samostatné WC | B11: 20 | C11: 5 | D11: =B11/60*Vstupy!$B$8 -> 100 | E11: =CEILING((D11+C11)/Vstupy!$B$45,Vstupy!$B$14) -> 200 | F11: =(E11-E11*(Vstupy!$B$41+Vstupy!$B$35)-D11-C11)/E11 -> 0.20444628 | G11: 140
A12: Balkon / terasa do 10 m² | B12: 25 | C12: 5 | D12: =B12/60*Vstupy!$B$8 -> 125 | E12: =CEILING((D12+C12)/Vstupy!$B$45,Vstupy!$B$14) -> 240 | F12: =(E12-E12*(Vstupy!$B$41+Vstupy!$B$35)-D12-C12)/E12 -> 0.18777961 | G12: 180
A13: 5. patro bez výtahu | B13: 20 | C13: 0 | D13: =B13/60*Vstupy!$B$8 -> 100 | E13: =CEILING((D13+C13)/Vstupy!$B$45,Vstupy!$B$14) -> 190 | F13: =(E13-E13*(Vstupy!$B$41+Vstupy!$B$35)-D13-C13)/E13 -> 0.20313049 | G13: 150 | H13: Ztráta času přenášením, ne úklid.
A15: Procentní příplatky (aplikují se na celkovou cenu)
A16: Příplatek | B16: Sazba | C16: Komu náleží | D16: Poznámka
A17: Expres (objednávka 2–4 h předem) | B17: 0.2 | C17: platforma | D17: Kompenzuje horší plánování a vyšší riziko neobsazení.
A18: Premium tier | B18: 0.25 | C18: dělit s uklízečkou | D18: Náročnější klient, eko chemie, zkušenější uklízečka – část musí jít jí.
A19: Silné znečištění (po zvířatech) | B19: 0.3 | C19: dělit s uklízečkou | D19: Odpovídá reálně delšímu času – jinak na tom uklízečka prodělá.
A20: Noční a víkendový úklid | B20: 0.25 | C20: převážně uklízečce | D20: Příplatek za nepohodlí patří tomu, kdo ho nese.
A22: Pozor: u příplatku za znečištění a za noční práci platí, že pokud si ho nechá celý platforma, uklízečka odpracuje víc hodin za stejné peníze – a to je přesně ten typ nerovnováhy, na který kouká inspektorát.

Sheet Posádka
A1: Více uklízeček na jedné zakázce
A2: Cena se počítá z CELKOVÝCH odpracovaných hodin, ne paušálním příplatkem 180 Kč/h. Marže tak drží u každé velikosti posádky.
A4: Zadání
A5: Plocha (m²) | B5: 90
A6: Typ (ESSENTIAL/DEEP) | B6: DEEP
A9: Uklízeček | B9: η efektivita | C9: Čas zakázky (h) | D9: Odpracováno celkem (h) | E9: Odměna celkem | F9: CENA NOVÁ | G9: Příspěvek Kč | H9: Příspěvek % | I9: Kč/h pro zákazníka | J9: Zkrácení času
A10: 1 | B10: 1 | C10: =$B$5*IF($B$6="DEEP",Vstupy!$B$22,Vstupy!$B$21)/(A10*B10)/60 -> 7.5 | D10: =C10*A10 -> 7.5 | E10: =D10*Vstupy!$B$8 -> 2250 | F10: =MAX(CEILING((E10+Vstupy!$B$36)/Vstupy!$B$45,Vstupy!$B$14),Vstupy!$B$13) -> 4340 | G10: =F10-F10*(Vstupy!$B$41+Vstupy!$B$35)-E10-Vstupy!$B$36 -> 786.04686 | H10: =G10/F10 -> 0.18111679 | I10: =F10/C10 -> 578.66667 | J10: =1-C10/$C$10 -> 0
A11: 2 | B11: 0.92 | C11: =$B$5*IF($B$6="DEEP",Vstupy!$B$22,Vstupy!$B$21)/(A11*B11)/60 -> 4.076087 | D11: =C11*A11 -> 8.1521739 | E11: =D11*Vstupy!$B$8 -> 2445.6522 | F11: =MAX(CEILING((E11+Vstupy!$B$36)/Vstupy!$B$45,Vstupy!$B$14),Vstupy!$B$13) -> 4690 | G11: =F11-F11*(Vstupy!$B$41+Vstupy!$B$35)-E11-Vstupy!$B$36 -> 845.70088 | H11: =G11/F11 -> 0.18032002 | I11: =F11/C11 -> 1150.6133 | J11: =1-C11/$C$10 -> 0.45652174
A12: 3 | B12: 0.82 | C12: =$B$5*IF($B$6="DEEP",Vstupy!$B$22,Vstupy!$B$21)/(A12*B12)/60 -> 3.0487805 | D12: =C12*A12 -> 9.1463415 | E12: =D12*Vstupy!$B$8 -> 2743.9024 | F12: =MAX(CEILING((E12+Vstupy!$B$36)/Vstupy!$B$45,Vstupy!$B$14),Vstupy!$B$13) -> 5240 | G12: =F12-F12*(Vstupy!$B$41+Vstupy!$B$35)-E12-Vstupy!$B$36 -> 948.64607 | H12: =G12/F12 -> 0.18103933 | I12: =F12/C12 -> 1718.72 | J12: =1-C12/$C$10 -> 0.59349593
A13: 4 | B13: 0.72 | C13: =$B$5*IF($B$6="DEEP",Vstupy!$B$22,Vstupy!$B$21)/(A13*B13)/60 -> 2.6041667 | D13: =C13*A13 -> 10.416667 | E13: =D13*Vstupy!$B$8 -> 3125 | F13: =MAX(CEILING((E13+Vstupy!$B$36)/Vstupy!$B$45,Vstupy!$B$14),Vstupy!$B$13) -> 5930 | G13: =F13-F13*(Vstupy!$B$41+Vstupy!$B$35)-E13-Vstupy!$B$36 -> 1070.8664 | H13: =G13/F13 -> 0.18058456 | I13: =F13/C13 -> 2277.12 | J13: =1-C13/$C$10 -> 0.65277778
A15: Každá uklízečka dostane svých 300 Kč/h za odpracovaný čas. Zákazník platí víc, ale má hotovo dřív – sloupec J říká o kolik. To je ten produkt, který prodáváš: rychlost.
A16: Původní příplatek 180 Kč/h za každou další uklízečku marži neudrží, protože každá další hodina práce stojí 300 Kč plus DPH a zatížení – reálně přes 500 Kč.

Sheet Ekonomika
A1: Ekonomika jedné zakázky při nových cenách
A2: Kontrolní rozklad. Poslední řádek musí být u všech sloupců nad cílovým příspěvkem.
A4: Položka | B4: ESSENTIAL M (2+kk) | C4: DEEP L (3+kk) | D4: Průměr balíčků | E4: Poznámka
A5: Cena zákazníka (vč. DPH) | B5: =Balíčky!L7 -> 1610 | C5: =Balíčky!L10 -> 3540 | D5: =Balíčky!L15 -> 3191 | E5: Nové ceny z listu Balíčky.
A6: − Odvod DPH | B6: =-B5*Vstupy!$B$41 -> -279.42149 | C6: =-C5*Vstupy!$B$41 -> -614.38017 | D6: =-D5*Vstupy!$B$41 -> -553.80992 | E6: 17,4 % z ceny, bez nároku na odpočet.
A7: − Slevy (Plus, tier, promo) | B7: =-B5*Vstupy!$B$28 -> -64.4 | C7: =-C5*Vstupy!$B$28 -> -141.6 | D7: =-D5*Vstupy!$B$28 -> -127.64
A8: − Poplatky Stripe (%) | B8: =-B5*Vstupy!$B$26 -> -22.54 | C8: =-C5*Vstupy!$B$26 -> -49.56 | D8: =-D5*Vstupy!$B$26 -> -44.674
A9: − Storna a refundace | B9: =-B5*Vstupy!$B$29 -> -32.2 | C9: =-C5*Vstupy!$B$29 -> -70.8 | D9: =-D5*Vstupy!$B$29 -> -63.82
A10: − Reklamace | B10: =-B5*Vstupy!$B$30 -> -32.2 | C10: =-C5*Vstupy!$B$30 -> -70.8 | D10: =-D5*Vstupy!$B$30 -> -63.82
A11: − Chargebacky | B11: =-B5*Vstupy!$B$31 -> -4.83 | C11: =-C5*Vstupy!$B$31 -> -10.62 | D11: =-D5*Vstupy!$B$31 -> -9.573
A12: − Odměna uklízečky | B12: =-Balíčky!I7 -> -750 | C12: =-Balíčky!I10 -> -1812.5 | D12: =-Balíčky!I15 -> -1620 | E12: Hodiny × 300 Kč/h (nebo dle přepínače).
A13: − Fixní náklady (Stripe fix, kredit, CAC) | B13: =-Vstupy!$B$36 -> -129.75 | C13: =-Vstupy!$B$36 -> -129.75 | D13: =-Vstupy!$B$36 -> -129.75
A14: PŘÍSPĚVEK NA ÚHRADU | B14: =SUM(B5:B13) -> 294.65851 | C14: =SUM(C5:C13) -> 639.98983 | D14: =SUM(D5:D13) -> 577.91308
A15: Příspěvek v % | B15: =B14/B5 -> 0.18301771 | C15: =C14/C5 -> 0.18078809 | D15: =D14/D5 -> 0.1811072
A16: Kontrola proti cíli | B16: =IF(B15>=Vstupy!$B$12-0.001,"OK","POD CÍLEM") -> OK | C16: =IF(C15>=Vstupy!$B$12-0.001,"OK","POD CÍLEM") -> OK | D16: =IF(D15>=Vstupy!$B$12-0.001,"OK","POD CÍLEM") -> OK
A17: Výdělek uklízečky (Kč/h) | B17: =Balíčky!I7/Balíčky!H7 -> 300 | C17: =Balíčky!I10/Balíčky!H10 -> 300 | D17: =Balíčky!I15/Balíčky!H15 -> 300

Sheet Měsíc
A1: Měsíční výsledek a bod zvratu při nových cenách
A2: Fixní náklady jsou odhad – přepiš je svými čísly.
A4: Ukazatel | B4: Rozjezd | C4: Provoz | D4: Škála | E4: Poznámka
A5: Počet zakázek za měsíc | B5: 100 | C5: 300 | D5: 800
A6: Průměrný příspěvek na zakázku | B6: =Ekonomika!$D$14 -> 577.91308 | C6: =Ekonomika!$D$14 -> 577.91308 | D6: =Ekonomika!$D$14 -> 577.91308 | E6: Z listu Ekonomika.
A7: Příspěvek ze zakázek | B7: =B5*B6 -> 57791.308 | C7: =C5*C6 -> 173373.92 | D7: =D5*D6 -> 462330.47
A8: Počet členů Cleansia Plus | B8: =B5*0.08 -> 8 | C8: =C5*0.08 -> 24 | D8: =D5*0.08 -> 64 | E8: Odhad 8 % zákazníků.
A9: Tržby z Plus (po DPH) | B9: =B8*199*(1-Vstupy!$B$41) -> 1315.7025 | C9: =C8*199*(1-Vstupy!$B$41) -> 3947.1074 | D9: =D8*199*(1-Vstupy!$B$41) -> 10525.62 | E9: 199 Kč/měsíc včetně DPH.
A10: Příspěvek celkem | B10: =B7+B9 -> 59107.011 | C10: =C7+C9 -> 177321.03 | D10: =D7+D9 -> 472856.09
A12: Fixní měsíční náklady
A13: Položka | B13: Kč/měsíc | E13: Poznámka
A14: Hosting Azure, databáze, úložiště | B14: 6000 | E14: Roste s objemem.
A15: SendGrid, Mapbox, Firebase, domény | B15: 1500
A16: Apple Developer + Google Play | B16: 300 | E16: Rozpočítáno z ročních poplatků.
A17: Účetnictví | B17: 5000
A18: Právní služby | B18: 8000 | E18: V prvním roce výrazně víc.
A19: Marketing nad rámec CAC (značka, obsah) | B19: 15000 | E19: CAC na zakázku je v listu Vstupy.
A20: Podpora a administrace | B20: 25000 | E20: Schvalování, reklamace, výplaty, refundace – dnes ručně.
A21: Pojištění platformy, ostatní | B21: 2500
A22: FIXNÍ NÁKLADY CELKEM | B22: =SUM(B14:B21) -> 63300
A24: Provozní výsledek (EBITDA) | B24: =B10-$B$22 -> -4192.9893 | C24: =C10-$B$22 -> 114021.03 | D24: =D10-$B$22 -> 409556.09
A25: Bod zvratu – zakázek za měsíc | B25: =ROUNDUP(($B$22)/(B6+199*(1-Vstupy!$B$41)*0.08),0) -> 108 | C25: =ROUNDUP(($B$22)/(C6+199*(1-Vstupy!$B$41)*0.08),0) -> 108 | D25: =ROUNDUP(($B$22)/(D6+199*(1-Vstupy!$B$41)*0.08),0) -> 108
A26: Zakázek denně (30 dní) | B26: =B25/30 -> 3.6 | C26: =C25/30 -> 3.6 | D26: =D25/30 -> 3.6

Sheet Citlivost
A1: Citlivost ceny na klíčové vstupy
A2: Cena balíčku DEEP L (72,5 m²) podle sazby uklízečky a režimu DPH. Ukazuje, o kolik je plátcovství DPH dražší pro zákazníka.
A4: Sazba uklízečky (Kč/h) | B4: Cena – plátce DPH | C4: Cena – neplátce DPH | D4: Rozdíl | E4: Kč/h pro zákazníka (plátce)
A5: 250 | B5: =CEILING((Balíčky!$H$10*A5+Vstupy!$B$36)/(1-(Vstupy!$B$40/(1+Vstupy!$B$40))-Vstupy!$B$35-Vstupy!$B$12),Vstupy!$B$14) -> 2990 | C5: =CEILING((Balíčky!$H$10*A5+Vstupy!$B$36)/(1-Vstupy!$B$35-Vstupy!$B$12),Vstupy!$B$14) -> 2270 | D5: =B5/C5-1 -> 0.31718062 | E5: =B5/Balíčky!$H$10 -> 494.89655
A6: 300 | B6: =CEILING((Balíčky!$H$10*A6+Vstupy!$B$36)/(1-(Vstupy!$B$40/(1+Vstupy!$B$40))-Vstupy!$B$35-Vstupy!$B$12),Vstupy!$B$14) -> 3540 | C6: =CEILING((Balíčky!$H$10*A6+Vstupy!$B$36)/(1-Vstupy!$B$35-Vstupy!$B$12),Vstupy!$B$14) -> 2690 | D6: =B6/C6-1 -> 0.31598513 | E6: =B6/Balíčky!$H$10 -> 585.93103
A7: 350 | B7: =CEILING((Balíčky!$H$10*A7+Vstupy!$B$36)/(1-(Vstupy!$B$40/(1+Vstupy!$B$40))-Vstupy!$B$35-Vstupy!$B$12),Vstupy!$B$14) -> 4090 | C7: =CEILING((Balíčky!$H$10*A7+Vstupy!$B$36)/(1-Vstupy!$B$35-Vstupy!$B$12),Vstupy!$B$14) -> 3110 | D7: =B7/C7-1 -> 0.31511254 | E7: =B7/Balíčky!$H$10 -> 676.96552
A8: 400 | B8: =CEILING((Balíčky!$H$10*A8+Vstupy!$B$36)/(1-(Vstupy!$B$40/(1+Vstupy!$B$40))-Vstupy!$B$35-Vstupy!$B$12),Vstupy!$B$14) -> 4640 | C8: =CEILING((Balíčky!$H$10*A8+Vstupy!$B$36)/(1-Vstupy!$B$35-Vstupy!$B$12),Vstupy!$B$14) -> 3530 | D8: =B8/C8-1 -> 0.31444759 | E8: =B8/Balíčky!$H$10 -> 768
A10: Vliv cílového příspěvku a marketingu (DEEP L, sazba dle Vstupů)
A11: Cílový příspěvek | B11: CAC 60 Kč | C11: CAC 120 Kč | D11: CAC 200 Kč
A12: 0.15 | B12: =CEILING((Balíčky!$H$10*Vstupy!$B$8+Vstupy!$B$27+Vstupy!$B$32*Vstupy!$B$33+60)/(1-Vstupy!$B$41-Vstupy!$B$35-A12),Vstupy!$B$14) -> 3250 | C12: =CEILING((Balíčky!$H$10*Vstupy!$B$8+Vstupy!$B$27+Vstupy!$B$32*Vstupy!$B$33+120)/(1-Vstupy!$B$41-Vstupy!$B$35-A12),Vstupy!$B$14) -> 3360 | D12: =CEILING((Balíčky!$H$10*Vstupy!$B$8+Vstupy!$B$27+Vstupy!$B$32*Vstupy!$B$33+200)/(1-Vstupy!$B$41-Vstupy!$B$35-A12),Vstupy!$B$14) -> 3490
A13: 0.18 | B13: =CEILING((Balíčky!$H$10*Vstupy!$B$8+Vstupy!$B$27+Vstupy!$B$32*Vstupy!$B$33+60)/(1-Vstupy!$B$41-Vstupy!$B$35-A13),Vstupy!$B$14) -> 3430 | C13: =CEILING((Balíčky!$H$10*Vstupy!$B$8+Vstupy!$B$27+Vstupy!$B$32*Vstupy!$B$33+120)/(1-Vstupy!$B$41-Vstupy!$B$35-A13),Vstupy!$B$14) -> 3540 | D13: =CEILING((Balíčky!$H$10*Vstupy!$B$8+Vstupy!$B$27+Vstupy!$B$32*Vstupy!$B$33+200)/(1-Vstupy!$B$41-Vstupy!$B$35-A13),Vstupy!$B$14) -> 3690
A14: 0.22 | B14: =CEILING((Balíčky!$H$10*Vstupy!$B$8+Vstupy!$B$27+Vstupy!$B$32*Vstupy!$B$33+60)/(1-Vstupy!$B$41-Vstupy!$B$35-A14),Vstupy!$B$14) -> 3700 | C14: =CEILING((Balíčky!$H$10*Vstupy!$B$8+Vstupy!$B$27+Vstupy!$B$32*Vstupy!$B$33+120)/(1-Vstupy!$B$41-Vstupy!$B$35-A14),Vstupy!$B$14) -> 3820 | D14: =CEILING((Balíčky!$H$10*Vstupy!$B$8+Vstupy!$B$27+Vstupy!$B$32*Vstupy!$B$33+200)/(1-Vstupy!$B$41-Vstupy!$B$35-A14),Vstupy!$B$14) -> 3970
A15: 0.25 | B15: =CEILING((Balíčky!$H$10*Vstupy!$B$8+Vstupy!$B$27+Vstupy!$B$32*Vstupy!$B$33+60)/(1-Vstupy!$B$41-Vstupy!$B$35-A15),Vstupy!$B$14) -> 3930 | C15: =CEILING((Balíčky!$H$10*Vstupy!$B$8+Vstupy!$B$27+Vstupy!$B$32*Vstupy!$B$33+120)/(1-Vstupy!$B$41-Vstupy!$B$35-A15),Vstupy!$B$14) -> 4060 | D15: =CEILING((Balíčky!$H$10*Vstupy!$B$8+Vstupy!$B$27+Vstupy!$B$32*Vstupy!$B$33+200)/(1-Vstupy!$B$41-Vstupy!$B$35-A15),Vstupy!$B$14) -> 4220
A17: Co z toho plyne: každých 10 Kč/h navíc pro uklízečku zdraží DEEP L zhruba o 110 Kč. Plátcovství DPH zdražuje o víc než čtvrtinu – pokud první rok zůstanete pod obratem 2 mil. Kč, je to zásadní cenová výhoda.

Sheet Přecenění
A1: Staré služby přepočítané novým vzorcem
A2: Řádky z původní kalkulace (Kalkulace_vsechny_doplnky_finalV1.xlsx) – kolik by musely stát, aby uklízečka měla svou sazbu a vám zbyla marže.
A4: Služba | B4: m² | C4: Hodin | D4: Odměna uklízečky | E4: CENA NOVÁ | F4: Původní cena | G4: Změna | H4: Verdikt původní ceny
A5: Jednorázový úklid do 50 m² | B5: 50 | C5: =B5*Vstupy!$B$22/60 -> 4.1666667 | D5: =C5*Vstupy!$B$8 -> 1250 | E5: =MAX(CEILING((D5+Vstupy!$B$36)/Vstupy!$B$45,Vstupy!$B$14),Vstupy!$B$13) -> 2520 | F5: 3000 | G5: =E5/F5-1 -> -0.16 | H5: =IF(F5<D5,"Původní cena nepokryla ani uklízečku","Původní cena byla nad novou") -> Původní cena byla nad novou
A6: Jednorázový úklid 50–100 m² | B6: 75 | C6: =B6*Vstupy!$B$22/60 -> 6.25 | D6: =C6*Vstupy!$B$8 -> 1875 | E6: =MAX(CEILING((D6+Vstupy!$B$36)/Vstupy!$B$45,Vstupy!$B$14),Vstupy!$B$13) -> 3650 | F6: 4125 | G6: =E6/F6-1 -> -0.11515152 | H6: =IF(F6<D6,"Původní cena nepokryla ani uklízečku","Původní cena byla nad novou") -> Původní cena byla nad novou
A7: Jednorázový úklid 100–200 m² | B7: 150 | C7: =B7*Vstupy!$B$22/60 -> 12.5 | D7: =C7*Vstupy!$B$8 -> 3750 | E7: =MAX(CEILING((D7+Vstupy!$B$36)/Vstupy!$B$45,Vstupy!$B$14),Vstupy!$B$13) -> 7070 | F7: 7500 | G7: =E7/F7-1 -> -0.057333333 | H7: =IF(F7<D7,"Původní cena nepokryla ani uklízečku","Původní cena byla nad novou") -> Původní cena byla nad novou
A8: Pravidelný úklid do 50 m² | B8: 50 | C8: =B8*Vstupy!$B$21/60 -> 2.5 | D8: =C8*Vstupy!$B$8 -> 750 | E8: =MAX(CEILING((D8+Vstupy!$B$36)/Vstupy!$B$45,Vstupy!$B$14),Vstupy!$B$13) -> 1610 | F8: 180 | G8: =E8/F8-1 -> 7.9444444 | H8: =IF(F8<D8,"Původní cena nepokryla ani uklízečku","Původní cena byla nad novou") -> Původní cena nepokryla ani uklízečku
A9: Pravidelný úklid 50–100 m² | B9: 75 | C9: =B9*Vstupy!$B$21/60 -> 3.75 | D9: =C9*Vstupy!$B$8 -> 1125 | E9: =MAX(CEILING((D9+Vstupy!$B$36)/Vstupy!$B$45,Vstupy!$B$14),Vstupy!$B$13) -> 2290 | F9: 277.5 | G9: =E9/F9-1 -> 7.2522523 | H9: =IF(F9<D9,"Původní cena nepokryla ani uklízečku","Původní cena byla nad novou") -> Původní cena nepokryla ani uklízečku
A10: Pravidelný úklid 100–200 m² | B10: 150 | C10: =B10*Vstupy!$B$21/60 -> 7.5 | D10: =C10*Vstupy!$B$8 -> 2250 | E10: =MAX(CEILING((D10+Vstupy!$B$36)/Vstupy!$B$45,Vstupy!$B$14),Vstupy!$B$13) -> 4340 | F10: 490 | G10: =E10/F10-1 -> 7.8571429 | H10: =IF(F10<D10,"Původní cena nepokryla ani uklízečku","Původní cena byla nad novou") -> Původní cena nepokryla ani uklízečku
A11: Úklid kanceláře do 50 m² | B11: 50 | C11: =B11*Vstupy!$B$21/60 -> 2.5 | D11: =C11*Vstupy!$B$8 -> 750 | E11: =MAX(CEILING((D11+Vstupy!$B$36)/Vstupy!$B$45,Vstupy!$B$14),Vstupy!$B$13) -> 1610 | F11: 210 | G11: =E11/F11-1 -> 6.6666667 | H11: =IF(F11<D11,"Původní cena nepokryla ani uklízečku","Původní cena byla nad novou") -> Původní cena nepokryla ani uklízečku
A12: Úklid kanceláře 50–100 m² | B12: 75 | C12: =B12*Vstupy!$B$21/60 -> 3.75 | D12: =C12*Vstupy!$B$8 -> 1125 | E12: =MAX(CEILING((D12+Vstupy!$B$36)/Vstupy!$B$45,Vstupy!$B$14),Vstupy!$B$13) -> 2290 | F12: 307.5 | G12: =E12/F12-1 -> 6.4471545 | H12: =IF(F12<D12,"Původní cena nepokryla ani uklízečku","Původní cena byla nad novou") -> Původní cena nepokryla ani uklízečku
A13: Úklid kanceláře 100–200 m² | B13: 150 | C13: =B13*Vstupy!$B$21/60 -> 7.5 | D13: =C13*Vstupy!$B$8 -> 2250 | E13: =MAX(CEILING((D13+Vstupy!$B$36)/Vstupy!$B$45,Vstupy!$B$14),Vstupy!$B$13) -> 4340 | F13: 525 | G13: =E13/F13-1 -> 7.2666667 | H13: =IF(F13<D13,"Původní cena nepokryla ani uklízečku","Původní cena byla nad novou") -> Původní cena nepokryla ani uklízečku
A15: Pravidelný úklid a kancelář by musely zdražit řádově – původní ceny 180 až 525 Kč nepokryjí ani hodinu práce uklízečky. Pokud chcete pravidelný úklid levnější, jediná legitimní páka je kratší rozsah (menší plocha, méně místností), ne nižší sazba.
